Workbook

Sheet BodyData-Timings
B1: Subject details | I1: OMRON Data | W1: Anthropometric Measurements | AF1: Motion Sensors | AM1: Pressure Sensor | AP1: Break Times | AV1: Data uploaded to nbox | BB1: Additional Comments
A2: Subject | B2: Date of visit | C2: Seat | D2: Chosen Angle | E2: First Break Recorded Angle | F2: Second Break Recorded Angle | G2: Sex | H2: Considered Obese (Body Fat) | I2: Weight (kg) | J2: Body Fat (%) | K2: Visceral Fat | L2: Resting Metabolism (kcal) | M2: Skeletal Muscle(%) | N2: Skeletal Muscle（ARMS）(%) | O2: Skeletal Muscle（TRUNK）(%) | P2: Skeletal Muscle（LEGS）(%) | Q2: Subcutaneous fat (%) | R2: Subcutaneous fat（ARMS）(%) | S2: Subcutaneous fat（TRUNK）(%) | T2: Subcutaneous fat（LEGS）(%) | U2: BMI | V2: Body Age (years old) | W2: Hip width 1 | X2: Hip width 2 (if any) | Y2: Average Hip width | Z2: Butt-Knee 1 | AA2: Butt-Knee 2 (if any) | AB2: Average Butt Knee | AC2: Popliteal 1 | AD2: Popliteal 2 (if any) | AE2: Average Popliteal | AF2: Start of S1 | AG2: End of S1 | AH2: Start of S2 | AI2: End of S2 | AJ2: Start of S3 | AK2: End of S3 | AL2: Issues/Comments (if any) | AM2: Start of recording | AN2: End of recording | AO2: Issues/Comments (if any) | AP2: Break 1 start time | AQ2: Break 1 end time | AR2: Duration (min) | AS2: Break 2 start time | AT2: Break 2 end time | AU2: Duration (min) | AV2: Motion Sensor | AW2: GCR | AX2: Pressure | AY2: Fitbit | AZ2: CCTV | BA2: Mini Cam | BB2: Participants movement, App glitches etc. | BC2: Obesity based on Body Fat % & BMI combined | BD2: Alignments with CCTV time
A3: A001 | B3: 45466 | C3: 2F | D3: 29 | G3: Male | H3: =IF(OR(AND(G3="Male",J3>=25),AND(G3="Female",J3>=32)),"Yes","No") -> No | I3: 80 | J3: 19.3 | K3: 8 | L3: 1798 | M3: 35 | N3: 38.3 | O3: 28.5 | P3: 52.2 | Q3: 13.6 | R3: 17.5 | S3: 12 | T3: 17.1 | U3: 23.4 | V3: 41 | W3: =57.3-16.1 -> 41.2 | Y3: =AVERAGE(W3,X3) -> 41.2 | Z3: 49.5 | AB3: =AVERAGE(Z3,AA3) -> 49.5 | AC3: 53.6 | AE3: =AVERAGE(AC3,AD3) -> 53.6 | AF3: 1.06pm | AG3: 3.07pm | AH3: 3.12pm | AI3: 5.13pm | AJ3: 5.19pm | AK3: 7.20pm | AM3: 1.06pm | AN3: 7.23pm | AP3: 3.07pm | AQ3: 3.12pm | AR3: 5 | AS3: 5.14pm | AT3: 5.19pm | AU3: 5 | BB3: 5.28pm - Using phone | BC3: =IF(AND(G3="Male", J3>25, U3>24.9), "Obese", IF(AND(G3="Female", J3>32, U3>24.9), "Obese", "Not Obese")) -> Not Obese | BE3: CCTV time is in-line with GCR
A4: A002 | B4: 45466 | C4: 3F | D4: 32 | G4: Male | H4: =IF(OR(AND(G4="Male",J4>=25),AND(G4="Female",J4>=32)),"Yes","No") -> No | I4: 75.7 | J4: 14.9 | K4: 6 | L4: 1754 | M4: 37.2 | N4: 40 | O4: 31.4 | P4: 54.3 | Q4: 10.6 | R4: 13.4 | S4: 9.3 | T4: 12.7 | U4: 22.1 | V4: 35 | W4: 40.1 | Y4: =AVERAGE(W4,X4) -> 40.1 | Z4: 47 | AB4: =AVERAGE(Z4,AA4) -> 47 | AC4: 50.5 | AE4: =AVERAGE(AC4,AD4) -> 50.5 | AF4: 1.04pm | AG4: 3.10pm | AH4: 3.15pm | AI4: 5.16pm | AJ4: 5.21pm | AK4: 7.23pm | AM4: 1.04pm | AN4: 7.24pm | AO4: Tekscan (back) disconnected for 20 - 25 mins after 2nd break | AP4: 3.10pm | AQ4: 3.15pm | AR4: 5 | AS4: 5.16pm | AT4: 5.21pm | AU4: 5 | BC4: =IF(AND(G4="Male", J4>25, U4>24.9), "Obese", IF(AND(G4="Female", J4>32, U4>24.9), "Obese", "Not Obese")) -> Not Obese | BE4: CCTV time is in-line with GCR
A5: A003 | B5: 45466 | C5: 3D | D5: 30 | G5: Female | H5: =IF(OR(AND(G5="Male",J5>=25),AND(G5="Female",J5>=32)),"Yes","No") -> No | I5: 59.4 | J5: 30.6 | K5: 4.5 | L5: 1261 | M5: 25.6 | N5: 27.4 | O5: 19.5 | P5: 37.5 | Q5: 25.1 | R5: 41.2 | S5: 21.7 | T5: 34.3 | U5: 21.3 | V5: 52 | W5: 40.8 | X5: 41.3 | Y5: =AVERAGE(W5,X5) -> 41.05 | Z5: 48.4 | AA5: 48.4 | AB5: =AVERAGE(Z5,AA5) -> 48.4 | AC5: 45 | AD5: 47 | AE5: =AVERAGE(AC5,AD5) -> 46 | AF5: 12.48pm | AG5: 2.57pm | AH5: 3.05pm | AI5: 5.07pm | AJ5: 5.13pm | AK5: 7.14pm | AM5: 12.51pm | AN5: 7.14pm | AO5: Tekscan closed on its own during session 1. Tekscan missing data: 12.51pm - 3.05pm (Laptop Crashed for Restart) & 4.53pm - 4.55pm (USB wires weak). | AP5: 2.58pm | AQ5: 3.04pm | AR5: 6 | AS5: 5.07pm | AT5: 5.12pm | AU5: 5 | BB5: GCR Notification popped up 10 minutes. Cabin Sound Disconnected on its own. Participant Lean to choose Netflix at 5.29pm | BC5: =IF(AND(G5="Male", J5>25, U5>24.9), "Obese", IF(AND(G5="Female", J5>32, U5>24.9), "Obese", "Not Obese")) -> Not Obese | BE5: CCTV time is in-line with GCR | BJ5: =COUNTIF(BC3:BC213,"Obese") -> 71
A6: A004 | B6: 45468 | C6: 3D | D6: 32 | G6: Female | H6: =IF(OR(AND(G6="Male",J6>=25),AND(G6="Female",J6>=32)),"Yes","No") -> No | I6: 57.6 | J6: 30.7 | K6: 4 | L6: 1232 | M6: 25.5 | N6: 27.6 | O6: 19.8 | P6: 37.6 | Q6: 25 | R6: 41.8 | S6: 21.6 | T6: 35.1 | U6: 21.2 | V6: 47 | W6: 41.2 | X6: 41.5 | Y6: =AVERAGE(W6,X6) -> 41.35 | Z6: 45.4 | AA6: 45.5 | AB6: =AVERAGE(Z6,AA6) -> 45.45 | AC6: 45.7 | AD6: 46 | AE6: =AVERAGE(AC6,AD6) -> 45.85 | AF6: 1.06pm | AG6: 3.12pm | AH6: 3.18pm | AI6: 5.18pm | AJ6: 5.24pm | AK6: 7.25pm | AM6: 1.09pm | AN6: 7.25pm | AP6: 3.12pm | AQ6: 3.17pm | AR6: 5 | AS6: 5.19pm | AT6: 5.24pm | AU6: 5 | BB6: 1.40pm - 1.41pm: Using Phone. 2.12pm - 2.13pm: Large movement (drinking water). First 20 minutes of Session 2: Using Phone. 3.39pm - 3.48pm: Still consuming food | BC6: =IF(AND(G6="Male", J6>25, U6>24.9), "Obese", IF(AND(G6="Female", J6>32, U6>24.9), "Obese", "Not Obese")) -> Not Obese | BE6: CCTV time is 1-2 second early; CCTV time: 15:12:09 GCR filled at 15:12:11 | BJ6: =COUNTIF(BC4:BC214,"Not Obese") -> 140
A7: A005 | B7: 45468 | C7: 3F | D7: 24 | G7: Female | H7: =IF(OR(AND(G7="Male",J7>=25),AND(G7="Female",J7>=32)),"Yes","No") -> Yes | I7: 70.1 | J7: 34.5 | K7: 9 | L7: 1410 | M7: 24.7 | N7: 24 | O7: 18 | P7: 38.4 | Q7: 31.2 | R7: 45.4 | S7: 27 | T7: 40.5 | U7: 27 | V7: 59 | W7: 43.4 | X7: 41.9 | Y7: =AVERAGE(W7,X7) -> 42.65 | Z7: 45.8 | AA7: 45.5 | AB7: =AVERAGE(Z7,AA7) -> 45.65 | AC7: 41.9 | AD7: 43.2 | AE7: =AVERAGE(AC7,AD7) -> 42.55 | AF7: 1.02pm | AG7: 3.03pm | AH7: 3.09pm | AI7: 5.09pm | AJ7: 5.17pm | AK7: 7.20pm | AM7: 1.02pm | AN7: 7.20pm | AO7: 2.23pm - 2.24pm: Adjust Pressure Mat Position | AP7: 3.04pm | AQ7: 3.09pm | AR7: 5 | AS7: 5.11pm | AT7: 5.16pm | AU7: 5 | BB7: 1.23pm - 1.24pm: Lean Forward to touch Screen. | BC7: =IF(AND(G7="Male", J7>25, U7>24.9), "Obese", IF(AND(G7="Female", J7>32, U7>24.9), "Obese", "Not Obese")) -> Obese | BE7: CCTV time is 1-2 second early; CCTV time: 15:03:56 GCR filled at 15:03:57
A8: A006 | B8: 45468 | C8: 2D | D8: 17 | G8: Female | H8: =IF(OR(AND(G8="Male",J8>=25),AND(G8="Female",J8>=32)),"Yes","No") -> Yes | I8: 64 | J8: 34.3 | K8: 7.5 | L8: 1314 | M8: 24.1 | N8: 24.6 | O8: 17.9 | P8: 37.1 | Q8: 29.6 | R8: 45.4 | S8: z | T8: 39.4 | U8: 25 | V8: 59 | W8: 40.8 | X8: 40.8 | Y8: =AVERAGE(W8,X8) -> 40.8 | Z8: 44.9 | AA8: 45.1 | AB8: =AVERAGE(Z8,AA8) -> 45 | AC8: 44 | AD8: 43.5 | AE8: =AVERAGE(AC8,AD8) -> 43.75 | AF8: 1.00pm | AG8: 3.03pm | AH8: 3.08pm | AI8: 5.09pm | AJ8: 5.15pm | AK8: 7.17pm | AL8: 1.43pm: Restart Metamotion (2D-R missing 5000 points) 1.43pm - 3.02pm: Missing Metamotion 2D-R (15,000 points). But sits in closed-leg position most of the time 3.13pm - 3.30pm: 2D-R Missing Metamotion 2D-R down for S3 | AM8: 1.01pm | AN8: 7.17pm | AP8: 3.03pm | AQ8: 3.08pm | AR8: 5 | AS8: 5.09pm | AT8: 5.14pm | AU8: 5 | BB8: GOPRO footage, first 4hr uploaded to nbox already 1.23pm - 1.24pm: Shift to talk to researcher 1.33pm: Shift to talk to researcher 2.43pm - 2.44pm: Stood up 3.38pm: Leg Stretching 4.03pm: Turn for Snacks | BC8: =IF(AND(G8="Male", J8>25, U8>24.9), "Obese", IF(AND(G8="Female", J8>32, U8>24.9), "Obese", "Not Obese")) -> Obese | BE8: CCTV time is 1-2 second early; CCTV time: 17:09:22 GCR filled at 17:09:24
A9: A007 | B9: 45468 | C9: 2F | D9: 30 | G9: Male | H9: =IF(OR(AND(G9="Male",J9>=25),AND(G9="Female",J9>=32)),"Yes","No") -> Yes | I9: 81.7 | J9: 29.1 | K9: 15 | L9: 1753 | M9: 29.2 | N9: 35.1 | O9: 21.3 | P9: 46.6 | Q9: 20.5 | R9: 27.7 | S9: 18.8 | T9: 28.1 | U9: 28.6 | V9: 54 | W9: 42.7 | X9: 42.7 | Y9: 49.6 | Z9: 49.6 | AA9: 49.6 | AB9: =AVERAGE(Z9,AA9) -> 49.6 | AC9: 47.4 | AD9: 47.2 | AE9: =AVERAGE(AC9,AD9) -> 47.3 | AF9: 12.41pm | AG9: 2.43pm | AH9: 2.47pm | AI9: 4.48pm | AJ9: 4.54pm | AK9: 6.54pm | AM9: 12.42pm | AN9: 6.55pm | AO9: 4.12pm: Adjust pressure mat | AP9: 2.43pm | AQ9: 2.48pm | AR9: 5 | AS9: 4.49pm | AT9: 4.54pm | AU9: 5 | BC9: =IF(AND(G9="Male", J9>25, U9>24.9), "Obese", IF(AND(G9="Female", J9>32, U9>24.9), "Obese", "Not Obese")) -> Obese | BE9: CCTV time is 1-2 second early; CCTV time: 14:42:39 GCR filled at 14:42:40
A10: A008 | B10: 45472 | C10: 2F | D10: 31 | G10: Male | H10: =IF(OR(AND(G10="Male",J10>=25),AND(G10="Female",J10>=32)),"Yes","No") -> Yes | I10: 79.2 | J10: 35.9 | K10: 11 | L10: 1682 | M10: 27.7 | N10: 34.9 | O10: 18.2 | P10: 45.2 | Q10: 24.1 | R10: 35.7 | S10: 21.6 | T10: 36.4 | U10: 25 | V10: 55 | W10: 42.4 | X10: 41.2 | Y10: =AVERAGE(W10,X10) -> 41.8 | Z10: 54.6 | AA10: 55.2 | AB10: =AVERAGE(Z10,AA10) -> 54.9 | AC10: 51.1 | AD10: 52.1 | AE10: =AVERAGE(AC10,AD10) -> 51.6 | AF10: 1.20pm | AG10: 3.21pm | AH10: 3.26pm | AI10: 5.27pm | AJ10: 5.32pm | AK10: 7.33pm | AM10: 1.20pm | AN10: 7.33pm | AP10: 3.21pm | AQ10: 3.26pm | AR10: 5 | AS10: 5.27pm | AT10: 5.32pm | AU10: 5 | BB10: GCR App Notifications Every 10 minutes 7.20pm - 7.26pm: Cabin Sound Disconnected | BC10: =IF(AND(G10="Male", J10>25, U10>24.9), "Obese", IF(AND(G10="Female", J10>32, U10>24.9), "Obese", "Not Obese")) -> Obese | BE10: CCTV time is in-line with GCR
A11: A009 | B11: 45472 | C11: 3F | D11: 24 | G11: Female | H11: =IF(OR(AND(G11="Male",J11>=25),AND(G11="Female",J11>=32)),"Yes","No") -> Yes | I11: 61.4 | J11: 37.1 | K11: 7 | L11: 1259 | M11: 22.4 | N11: 23.3 | O11: 17 | P11: 35.1 | Q11: 31.2 | R11: 50.3 | S11: 28 | T11: 44.7 | U11: 25.2 | V11: 53 | W11: 46 | X11: 45.7 | Y11: =AVERAGE(W11,X11) -> 45.85 | Z11: 40 | AA11: 46 | AB11: =AVERAGE(Z11,AA11) -> 43 | AC11: 43 | AD11: 43.2 | AE11: =AVERAGE(AC11,AD11) -> 43.1 | AF11: 1.30pm | AG11: 3.38pm | AH11: 3.44pm | AI11: 5.44pm | AJ11: 5.50pm | AK11: 7.51pm | AM11: 1.37pm | AN11: 7.51pm | AO11: 1.17pm - 1.21pm: Tekscan got disconnected initially for 3-4 mins 2.30pm - 2.33pm: Tekscan disconnected 3.28pm - 3.29pm: Tekscan disconnected | AP11: 3.38pm | AQ11: 3.44pm | AR11: 6 | AS11: 5.45pm | AT11: 5.50pm | AU11: 5 | BB11: GCR: 1.39pm, 1.49pm, 1.59pm, 2.00pm, 2.19pm (GCR popped up every 10 mins) 5.12pm: Readjusted mini cam angle 7.20pm - 7.26pm: Cabin sound disconnected | BC11: =IF(AND(G11="Male", J11>25, U11>24.9), "Obese", IF(AND(G11="Female", J11>32, U11>24.9), "Obese", "Not Obese")) -> Obese | BE11: CCTV time is in-line with GCR
A12: A010 | B12: 45474 | C12: 2F | D12: 19 | G12: Male | H12: =IF(OR(AND(G12="Male",J12>=25),AND(G12="Female",J12>=32)),"Yes","No") -> Yes | I12: 98 | J12: 30.8 | K12: 20 | L12: 2003 | M12: 29.1 | N12: 33.5 | O12: 20.8 | P12: 46.5 | Q12: 21.9 | R12: 26.7 | S12: 20.2 | T12: 27.4 | U12: 30.6 | V12: 67 | W12: 46.3 | X12: 46.8 | Y12: =AVERAGE(W12,X12) -> 46.55 | Z12: 52 | AA12: 52 | AB12: =AVERAGE(Z12,AA12) -> 52 | AC12: 53.2 | AD12: 53 | AE12: =AVERAGE(AC12,AD12) -> 53.1 | AF12: 1.20pm | AG12: 3.22pm | AH12: 3.28pm | AI12: 5.29pm | AJ12: 5.35pm | AK12: 7.36pm | AM12: 1.20pm | AN12: 7.36pm | AO12: 5.09pm: Adjust Pressure Mat (Back). Frames 13600 6.15pm: Adjust Presssure Mat (Back). Frames 17480 | AP12: 3.22pm | AQ12: 3.28pm | AR12: 6 | AS12: 5.30pm | AT12: 5.35pm | AU12: 5 | BB12: 2.01pm - 2.16pm: Holding on to keyboard Movements (Lean Forward) whenver notification rings GCR App Notifications Dupicate - Disabled Notifications 4.42pm - 4.47pm: Cabin Sound Disconnected | BC12: =IF(AND(G12="Male", J12>25, U12>24.9), "Obese", IF(AND(G12="Female", J12>32, U12>24.9), "Obese", "Not Obese")) -> Obese | BE12: CCTV time is 1 second early; CCTV time: 15:22:02 GCR filled at 15:22:03
A13: A011 | B13: 45474 | C13: 3D | D13: 23 | G13: Female | H13: =IF(OR(AND(G13="Male",J13>=25),AND(G13="Female",J13>=32)),"Yes","No") -> No | I13: 53 | J13: 28.6 | K13: 4 | L13: 1167 | M13: 25.8 | N13: 29 | O13: 20.3 | P13: 38.3 | Q13: 24.4 | R13: 39.2 | S13: 20.5 | T13: 33.6 | U13: 21.8 | V13: 44 | W13: 36.5 | X13: 36.2 | Y13: =AVERAGE(W13,X13) -> 36.35 | Z13: 47 | AA13: 46.9 | AB13: =AVERAGE(Z13,AA13) -> 46.95 | AC13: 42 | AD13: 44 | AE13: =AVERAGE(AC13,AD13) -> 43 | AF13: 12.22pm | AG13: 2.24pm | AH13: 2.28pm | AI13: 4.29pm | AJ13: 4.34pm | AK13: 6.34pm | AL13: 1.14pm: Motion Sensor Loss 10000 points. Saved & Reset Motion Sensor 4.08pm - 4.28pm: 3D_R Motion Sensor not captured 5.21pm - 5.22pm: Restarted Motion Sensor | AM13: 12.22pm | AN13: 6.34pm | AO13: 3.09pm: Adjust Pressure Mat. Frames 9850 - 9950 5.21pm - 5.22pm: Adjust Presssure Mat | AP13: 2.23pm | AQ13: 2.28pm | AR13: 5 | AS13: 4.29pm | AT13: 4.34pm | AU13: 5 | BB13: 3.29pm - 3.30pm: Went to Toilet. Frames 11115 4.42pm - 4.47pm: Cabin Sound Disconnected 5.19pm - 5.21pm: Went to Toilet | BC13: =IF(AND(G13="Male", J13>25, U13>24.9), "Obese", IF(AND(G13="Female", J13>32, U13>24.9), "Obese", "Not Obese")) -> Not Obese | BE13: CCTV time is 1 second early; CCTV time: 14:22:57 GCR filled at 14:22:58
A14: A012 | B14: 45474 | C14: 3F | D14: 25 | G14: Male | H14: =IF(OR(AND(G14="Male",J14>=25),AND(G14="Female",J14>=32)),"Yes","No") -> Yes | I14: 70.7 | J14: 31.6 | K14: 15 | L14: 1557 | M14: 26.7 | N14: 34.1 | O14: 18.8 | P14: 44.2 | Q14: 21.7 | R14: 29.6 | S14: 19.7 | T14: 30.1 | U14: 26.9 | V14: 59 | W14: 40.9 | X14: 41 | Y14: =AVERAGE(W14,X14) -> 40.95 | Z14: 47.5 | AA14: 47.3 | AB14: =AVERAGE(Z14,AA14) -> 47.4 | AC14: 42.6 | AD14: 42.6 | AE14: =AVERAGE(AC14,AD14) -> 42.6 | AF14: 1.07pm | AG14: 3.09pm | AH14: 3.15pm | AI14: 5.17pm | AJ14: 5.22pm | AK14: 7.23pm | AM14: 1.07pm | AN14: 7.23pm | AO14: 3.58pm: Adjust Pressure Mat (Back) Frame 10100 4.21pm: Adjust Pressure Mat (Back) Frame 11500 6.23pm: Adjust Pressure Mat (Back) Frame 18750 | AP14: 3.09pm | AQ14: 3.15pm | AR14: 6 | AS14: 5.17pm | AT14: 5.22pm | AU14: 5 | BB14: 1.30pm - 1.31pm: Movements due to researcher (pts missed the rating) 4.42pm - 4.47pm: Cabin Sound Disconnected 7.11pm: Drinking Water | BC14: =IF(AND(G14="Male", J14>25, U14>24.9), "Obese", IF(AND(G14="Female", J14>32, U14>24.9), "Obese", "Not Obese")) -> Obese | BE14: CCTV time is 1 second early; CCTV time: 17:16:59 GCR filled at 17:17:00
A15: A013 | B15: 45475 | C15: 3F | D15: 30 | G15: Male | H15: =IF(OR(AND(G15="Male",J15>=25),AND(G15="Female",J15>=32)),"Yes","No") -> Yes | I15: 70.2 | J15: 28 | K15: 8 | L15: 1583 | M15: 30.5 | N15: 37.2 | O15: 22.6 | P15: 47.9 | Q15: 18.9 | R15: 27.2 | S15: 16.7 | T15: 27.4 | U15: 22.9 | V15: 44 | W15: 38.3 | X15: 39.5 | Y15: =AVERAGE(W15,X15) -> 38.9 | Z15: 49.5 | AA15: 49.5 | AB15: =AVERAGE(Z15,AA15) -> 49.5 | AC15: 48.4 | AD15: 48.6 | AE15: =AVERAGE(AC15,AD15) -> 48.5 | AF15: 12.24pm | AG15: 2.32pm | AH15: 2.37pm | AI15: 4.37pm | AJ15: 4.43pm | AK15: 6.44pm | AM15: 12.24pm | AN15: 6.45pm | AO15: 6.05pm: Adjust Pressure Mat (Back) Frame 20200~ | AP15: 2.31pm | AQ15: 2.36pm | AR15: 5 | AS15: 4.38pm | AT15: 4.43pm | AU15: 5 | BC15: =IF(AND(G15="Male", J15>25, U15>24.9), "Obese", IF(AND(G15="Female", J15>32, U15>24.9), "Obese", "Not Obese")) -> Not Obese | BE15: CCTV time is in-line with GCR
A16: A014 | B16: 45475 | C16: 3D | D16: 19 | G16: Female | H16: =IF(OR(AND(G16="Male",J16>=25),AND(G16="Female",J16>=32)),"Yes","No") -> Yes | I16: 52.7 | J16: 37.5 | K16: 5.5 | L16: 1127 | M16: 21.9 | N16: 24.5 | O16: 17.1 | P16: 33.5 | Q16: 29.6 | R16: 50.7 | S16: 27.1 | T16: 43.1 | U16: 22.8 | V16: 48 | W16: 39.9 | X16: 40 | Y16: =AVERAGE(W16,X16) -> 39.95 | Z16: 38.9 | AA16: 38 | AB16: =AVERAGE(Z16,AA16) -> 38.45 | AC16: 40.7 | AD16: 39.9 | AE16: =AVERAGE(AC16,AD16) -> 40.3 | AF16: 12.53pm | AG16: 2.54pm | AH16: 3.01pm | AI16: 5.02pm | AJ16: 5.07pm | AK16: 7.08pm | AL16: 1.55pm - 1.57pm: 3D_L Disconnected 4.41pm: Motion Sensor Disconnected | AM16: 12.52pm | AN16: 7.08pm | AP16: 2.54pm | AQ16: 3.01pm | AR16: 7 | AS16: 5.02pm | AT16: 5.07pm | AU16: 5 | BB16: 1.58pm: Turn to call Researcher 2.02pm - 2.05pm: Earpiece Disconnected. Change Earpiee 2.59pm: Participant removed Fitbit to wash hands 3.01pm: Participant Snacking 6.08pm: Turn to talk to Researcher 6.33pm - 6.35pm: Went Toilet (Frame 22250) | BC16: =IF(AND(G16="Male", J16>25, U16>24.9), "Obese", IF(AND(G16="Female", J16>32, U16>24.9), "Obese", "Not Obese")) -> Not Obese | BE16: CCTV time is in-line with GCR
A17: A015 | B17: 45478 | C17: 2F | D17: 30 | G17: Male | H17: =IF(OR(AND(G17="Male",J17>=25),AND(G17="Female",J17>=32)),"Yes","No") -> Yes | I17: 72 | J17: 28.7 | K17: 12.5 | L17: 1596 | M17: 28.3 | N17: 34.8 | O17: 20.8 | P17: 45.8 | Q17: 19.7 | R17: 26.2 | S17: 17.7 | T17: 26.6 | U17: 25.2 | V17: 57 | W17: 40.4 | X17: 41.1 | Y17: =AVERAGE(W17,X17) -> 40.75 | Z17: 49.4 | AA17: 48.9 | AB17: =AVERAGE(Z17,AA17) -> 49.15 | AC17: 48.5 | AD17: 47 | AE17: =AVERAGE(AC17,AD17) -> 47.75 | AF17: 1.11pm | AG17: 3.12pm | AH17: 3.17pm | AI17: 5.19pm | AJ17: 5.24pm | AK17: 7.25pm | AM17: 1.11pm | AN17: 7.26pm | AP17: 3.13pm | AQ17: 3.18pm | AR17: 5 | AS17: 5.19pm | AT17: 5.24pm | AU17: 5 | BC17: =IF(AND(G17="Male", J17>25, U17>24.9), "Obese", IF(AND(G17="Female", J17>32, U17>24.9), "Obese", "Not Obese")) -> Obese | BE17: CCTV time is in-line with GCR
A18: A0SQ | B18: 45478 | C18: 3F | D18: 20 | G18: Female | H18: =IF(OR(AND(G18="Male",J18>=25),AND(G18="Female",J18>=32)),"Yes","No") -> Yes | I18: 61.6 | J18: 35.2 | K18: 6 | L18: 1272 | M18: 23.5 | N18: 24.4 | O18: 18 | P18: 35.7 | Q18: 29.4 | R18: 48 | S18: 26.2 | T18: 42.2 | U18: 24.1 | V18: 50 | W18: 41.9 | X18: 42.4 | Y18: =AVERAGE(W18,X18) -> 42.15 | Z18: 47.2 | AA18: 47.9 | AB18: =AVERAGE(Z18,AA18) -> 47.55 | AC18: 39.7 | AD18: 40.7 | AE18: =AVERAGE(AC18,AD18) -> 40.2 | AF18: 12.35pm | AG18: 2.36pm | AH18: 2.43pm | AI18: 4.45pm | AJ18: 4.50pm | AK18: 6.51pm | AL18: 3.46pm: Motion Sensor right not recording > Restarted at 3.47pm 5.30pm - 5.34pm: Motion Sensor Lost Connection 6.04pm - 6.05pm: Restart Motion Sensor (3F_R Connection Issue - remember to reboot) | AM18: 12.35pm | AN18: 6.51pm | AP18: 2.36pm | AQ18: 2.43pm | AR18: 7 | AS18: 4.45pm | AT18: 4.50pm | AU18: 5 | BB18: 5.04pm - 5.06pm: Participant stood up, got out of seat | BC18: =IF(AND(G18="Male", J18>25, U18>24.9), "Obese", IF(AND(G18="Female", J18>32, U18>24.9), "Obese", "Not Obese")) -> Not Obese
A19: A016 | B19: 45478 | C19: 3D | D19: 28 | G19: Female | H19: =IF(OR(AND(G19="Male",J19>=25),AND(G19="Female",J19>=32)),"Yes","No") -> Yes | I19: 69.3 | J19: 38 | K19: 7 | L19: 1377 | M19: 22.8 | N19: 22 | O19: 17 | P19: 35 | Q19: 31.1 | R19: 51.5 | S19: 28.3 | T19: 45.2 | U19: 24.6 | V19: 58 | W19: 44.2 | X19: 44.4 | Y19: =AVERAGE(W19,X19) -> 44.3 | Z19: 48.5 | AA19: 48.8 | AB19: =AVERAGE(Z19,AA19) -> 48.65 | AC19: 45 | AD19: 45.2 | AE19: =AVERAGE(AC19,AD19) -> 45.1 | AF19: 12.37pm | AG19: 2.42pm | AH19: 2.49pm | AI19: 4.49pm | AJ19: 4.55pm | AK19: 6.56pm | AM19: 12.41pm | AN19: 6.57pm | AP19: 2.43pm | AQ19: 2.48pm | AR19: 5 | AS19: 4.50pm | AT19: 4.55pm | AU19: 5 | BB19: 2.23pm - 2.26pm: Toilet | BC19: =IF(AND(G19="Male", J19>25, U19>24.9), "Obese", IF(AND(G19="Female", J19>32, U19>24.9), "Obese", "Not Obese")) -> Not Obese | BE19: CCTV time is in-line with GCR
A20: A017 | B20: 45479 | C20: 2D | D20: 15 | G20: Male | H20: =IF(OR(AND(G20="Male",J20>=25),AND(G20="Female",J20>=32)),"Yes","No") -> Yes | I20: 75.6 | J20: 29.8 | K20: 16 | L20: 1646 | M20: 27.9 | N20: 34.2 | O20: 20.1 | P20: 45.3 | Q20: 20.8 | R20: 27.8 | S20: 19 | T20: 28.2 | U20: 28.1 | V20: 58 | W20: 41.1 | X20: 41 | Y20: =AVERAGE(W20,X20) -> 41.05 | Z20: 44.9 | AA20: 45 | AB20: =AVERAGE(Z20,AA20) -> 44.95 | AC20: 40 | AD20: 42.3 | AE20: =AVERAGE(AC20,AD20) -> 41.15 | AF20: 1.06pm | AG20: 3.06pm | AH20: 3.12pm | AI20: 5.12pm | AJ20: 5.18pm | AK20: 7.19pm | AL20: Motion Sensors missing data ~ 22800 points only. 3.02pm Restarted. Motion Sensors missing data. 2D_L Restarted at 4.32pm | AM20: 1.04pm | AN20: 7.19pm | AO20: Frame 114: Start of Study | AP20: 3.06pm | AQ20: 3.11pm | AR20: 5 | AS20: 5.12pm | AT20: 5.17pm | AU20: 5 | BB20: 1.48pm - 1.53pm: WIFI Disconnected 6.43pm: GCR did not record for 6.38pm. Participant told to fill in GCR again | BC20: =IF(AND(G20="Male", J20>25, U20>24.9), "Obese", IF(AND(G20="Female", J20>32, U20>24.9), "Obese", "Not Obese")) -> Obese | BE20: CCTV time is 4 second early; CCTV time: 15:06:07 GCR filled at 15:06:11
A21: A018 | B21: 45479 | C21: 2F | D21: 32 | G21: Male | H21: =IF(OR(AND(G21="Male",J21>=25),AND(G21="Female",J21>=32)),"Yes","No") -> Yes | I21: 89 | J21: 30.1 | K21: 21 | L21: 1860 | M21: 28.6 | N21: 33.6 | O21: 20.6 | P21: 46.1 | Q21: 21.6 | R21: 26.5 | S21: 20.1 | T21: 27.1 | U21: 31.5 | V21: 64 | W21: 47 | X21: 47 | Y21: =AVERAGE(W21,X21) -> 47 | Z21: 47.5 | AA21: 47.3 | AB21: =AVERAGE(Z21,AA21) -> 47.4 | AC21: 45.8 | AD21: 46 | AE21: =AVERAGE(AC21,AD21) -> 45.9 | AF21: 1.06pm | AG21: 3.11pm | AH21: 3.18pm | AI21: 5.19pm | AJ21: 5.25pm | AK21: 7.25pm | AM21: 1.07pm | AN21: 7.27pm | AO21: Frame 220: Start of Study | AP21: 3.12pm | AQ21: 3.17pm | AR21: 5 | AS21: 5.20pm | AT21: 5.25pm | AU21: 5 | BC21: =IF(AND(G21="Male", J21>25, U21>24.9), "Obese", IF(AND(G21="Female", J21>32, U21>24.9), "Obese", "Not Obese")) -> Obese | BE21: CCTV time is 4 second early; CCTV time: 17:19:37 GCR filled at 17:19:41
A22: A019 | B22: 45479 | C22: 3D | D22: 23 | G22: Female | H22: =IF(OR(AND(G22="Male",J22>=25),AND(G22="Female",J22>=32)),"Yes","No") -> Yes | I22: 55.5 | J22: 35 | K22: 7.5 | L22: 1177 | M22: 22.6 | N22: 24.7 | O22: 17.1 | P22: 35.3 | Q22: 29.7 | R22: 46.7 | S22: 26.3 | T22: 40.6 | U22: 24.7 | V22: 55 | W22: 40.2 | X22: 40.1 | Y22: =AVERAGE(W22,X22) -> 40.15 | Z22: 42.5 | AA22: 42.8 | AB22: =AVERAGE(Z22,AA22) -> 42.65 | AC22: 39.5 | AD22: 38.4 | AE22: =AVERAGE(AC22,AD22) -> 38.95 | AF22: 1.02pm | AG22: 3.04pm | AH22: 3.09pm | AI22: 5.10pm | AJ22: 5.16pm | AK22: 7.17pm | AL22: 2.22pm: 3D_R Disconnected 3.48pm: 3D_R Disconnected 4.10pm 3D_R Disconnected | AM22: 1.02pm | AN22: 7.17pm | AO22: Tekscan stopped at Frame 2995 1.52pm. Restarted at 2.27pm 6.06pm: Adjust Pressure Mat (Back) Frame 13000 Tekscan stopped at Frame 15253. 6.49pm. Restarted at 6.53pm 6.57pm: Adjust Pressure Mat (Both) Frame 300 | AP22: 3.04pm | AQ22: 3.09pm | AR22: 5 | AS22: 5.10pm | AT22: 5.16pm | AU22: 6 | BB22: 1.22pm: Movement to fill in GCR 1.24pm: Movement to ask question 2.48pm: Movement to ask question | BC22: =IF(AND(G22="Male", J22>25, U22>24.9), "Obese", IF(AND(G22="Female", J22>32, U22>24.9), "Obese", "Not Obese")) -> Not Obese | BE22: CCTV time is 4 second early; CCTV time: 17:10:36 GCR filled at 17:10:40
A23: A020 | B23: 45479 | C23: 3F | D23: 20 | G23: Female | H23: =IF(OR(AND(G23="Male",J23>=25),AND(G23="Female",J23>=32)),"Yes","No") -> Yes | I23: 76 | J23: 37 | K23: 13 | L23: 1486 | M23: 23.9 | N23: 21.8 | O23: 16.6 | P23: 38.2 | Q23: 35.2 | R23: 47.9 | S23: 30.6 | T23: 44.3 | U23: 30.8 | V23: 64 | W23: 42.1 | X23: 43.4 | Y23: =AVERAGE(W23,X23) -> 42.75 | Z23: 46 | AA23: 46 | AB23: =AVERAGE(Z23,AA23) -> 46 | AC23: 39.8 | AD23: 39 | AE23: =AVERAGE(AC23,AD23) -> 39.4 | AF23: 12.17pm | AG23: 2.18pm | AH23: 2.23pm | AI23: 4.24pm | AJ23: 4.29pm | AK23: 6.30pm | AL23: 1.37pm: 3F_R Disconnected 1.57pm: 3F_R Disconnected 3.24pm: 3F_R Disconnected 3.43pm - 3.47pm: 3F_R Disconnected 4.03pm: 3F_R Disconnected. Lost 2000 points 4.11pm: 3F_R Disconnected | AM23: 12.17pm | AN23: 6.30pm | AO23: 3.52pm; Adjust Pressure Mat Frame 12800. Participant was stretching | AP23: 2.18pm | AQ23: 2.23pm | AR23: 5 | AS23: 4.24pm | AT23: 4.29pm | AU23: 5 | BB23: 2.32pm: Turn to talk to Researcher | BC23: =IF(AND(G23="Male", J23>25, U23>24.9), "Obese", IF(AND(G23="Female", J23>32, U23>24.9), "Obese", "Not Obese")) -> Obese | BE23: CCTV time is 3 second early; CCTV time: 14:17:52 GCR filled at 14:17:55
A24: A021 | B24: 45481 | C24: 2F | D24: 31 | G24: Female | H24: =IF(OR(AND(G24="Male",J24>=25),AND(G24="Female",J24>=32)),"Yes","No") -> No | I24: 50.2 | J24: 29.3 | K24: 3 | L24: 1120 | M24: 25.2 | N24: 28.9 | O24: 19.9 | P24: 37.2 | Q24: 23.2 | R24: 39.8 | S24: 19.9 | T24: 32.4 | U24: 19.6 | V24: 45 | W24: 38.8 | X24: 38.4 | Y24: =AVERAGE(W24,X24) -> 38.6 | Z24: 44 | AA24: 44.3 | AB24: =AVERAGE(Z24,AA24) -> 44.15 | AC24: 43.4 | AD24: 44 | AE24: =AVERAGE(AC24,AD24) -> 43.7 | AF24: 12.54pm | AG24: 2.54pm | AH24: 3.00pm | AI24: 5.01pm | AJ24: 5.06pm | AK24: 7.07pm | AM24: 12.53pm | AN24: 7.07pm | AP24: 2.54pm | AQ24: 3.00pm | AR24: 6 | AS24: 5.01pm | AT24: 5.06pm | AU24: 5 | BB24: 3.17pm - 3.19pm: Excessive Movements (Talking, Eating, etc) 5.27pm: Subject Using Phone 6.29pm - 6.31pm: Went Toilet (Frame 19950) 6.33pm: Gave Subject Paracetamol for Headache) 6.36pm: Subject Using Phone | BC24: =IF(AND(G24="Male", J24>25, U24>24.9), "Obese", IF(AND(G24="Female", J24>32, U24>24.9), "Obese", "Not Obese")) -> Not Obese | BE24: CCTV time is in-line with GCR
A25: A022 | B25: 45481 | C25: 2D | D25: 24 | G25: Female | H25: =IF(OR(AND(G25="Male",J25>=25),AND(G25="Female",J25>=32)),"Yes","No") -> No | I25: 43.3 | J25: 26.8 | K25: 1.5 | L25: 1018 | M25: 25.4 | N25: 30.6 | O25: 20.6 | P25: 36.1 | Q25: 20.5 | R25: 37 | S25: 17.3 | T25: 29.2 | U25: 17.6 | V25: 38 | W25: 36.3 | X25: 35.3 | Y25: =AVERAGE(W25,X25) -> 35.8 | Z25: 44.2 | AA25: 42.8 | AB25: =AVERAGE(Z25,AA25) -> 43.5 | AC25: 40.5 | AD25: 43.5 | AE25: =AVERAGE(AC25,AD25) -> 42 | AF25: 12.57pm | AG25: 2.58pm | AH25: 3.05pm | AI25: 5.09pm | AJ25: 5.15pm | AK25: 7.14pm | AL25: 1.05pm: 2D_R Stopped (up to 190 points) 5.15pm - 5.28pm: 2D_R Missing Data | AM25: 12.57pm | AN25: 7.14pm | AO25: 1.08pm: Check Tekscan (Back) Frame 650~ | AP25: 2.58pm | AQ25: 3.03pm | AR25: 5 | AS25: 5.09pm | AT25: 5.14pm | AU25: 5 | BB25: 1.59pm - 2.01pm: Movements due to researcher 2.04pm - 2.05pm: Movements due to researcher 3.10pm - 3.11pm: Movements due to researcher (eating) 3.17pm - 3.19pm: Movements due to researcher (talking / turning) 3,37pm - 3.38pm: Movements due to researcher (leaning forward for the screen) | BC25: =IF(AND(G25="Male", J25>25, U25>24.9), "Obese", IF(AND(G25="Female", J25>32, U25>24.9), "Obese", "Not Obese")) -> Not Obese | BE25: CCTV time is in-line with GCR
A26: A023 | B26: 45481 | C26: 3D | D26: 32 | E26: 36 | F26: 41 | G26: Male | H26: =IF(OR(AND(G26="Male",J26>=25),AND(G26="Female",J26>=32)),"Yes","No") -> Yes | I26: 110.8 | J26: 33.7 | K26: 23 | L26: 2183 | M26: 28.3 | N26: 32.8 | O26: 19.3 | P26: 45.7 | Q26: 24.4 | R26: 31.1 | S26: 23 | T26: 31.9 | U26: 35 | V26: 66 | W26: 54.6 | X26: 55.7 | Y26: =AVERAGE(W26,X26) -> 55.15 | Z26: 53.8 | AA26: 53.6 | AB26: =AVERAGE(Z26,AA26) -> 53.7 | AC26: 47.7 | AD26: 49.6 | AE26: =AVERAGE(AC26,AD26) -> 48.65 | AF26: 1.28pm | AG26: 3.28pm | AH26: 3.33pm | AI26: 5.29pm | AJ26: 5.37pm | AK26: 7.38pm | AM26: 1.28pm | AN26: 7.38pm | AO26: 5.24pm - 5.37pm: Tekscan (Back) Slipped down. Lost Connection | AP26: 3.28pm | AQ26: 3.33pm | AR26: 5 | AS26: 5.29pm | AT26: 5.37pm | AU26: 8 | BB26: 3.35pm - 3.37pm: Touching Screeen (but does not lean forward) Mentioned that Subject could not lean towards right. Hence more weight on LHS, Higher Discomfort Scores. In general, Subject experienced moderate discomfort | BC26: =IF(AND(G26="Male", J26>25, U26>24.9), "Obese", IF(AND(G26="Female", J26>32, U26>24.9), "Obese", "Not Obese")) -> Obese | BE26: CCTV time is in-line with GCR
A27: A024 | B27: 45482 | C27: 2D | D27: 31 | G27: Male | H27: =IF(OR(AND(G27="Male",J27>=25),AND(G27="Female",J27>=32)),"Yes","No") -> No | I27: 55.9 | J27: 22.3 | K27: 4.5 | L27: 1376 | M27: 32.1 | N27: 38.7 | O27: 25.5 | P27: 49.4 | Q27: 14.8 | R27: 21.4 | S27: 12.7 | T27: 21.2 | U27: 19.8 | V27: 31 | W27: 36.7 | X27: 36.7 | Y27: =AVERAGE(W27,X27) -> 36.7 | Z27: 46.2 | AA27: 46.1 | AB27: =AVERAGE(Z27,AA27) -> 46.15 | AC27: 47.1 | AD27: 47.3 | AE27: =AVERAGE(AC27,AD27) -> 47.2 | AF27: 1.29pm | AG27: 3.30pm | AH27: 3.36pm | AI27: 5.37pm | AJ27: 5.43pm | AK27: 7.44pm | AL27: 4.56pm: 2D_R Disconnected. Loss 13000 Points | AM27: 1.30pm | AN27: 7.44pm | AP27: 3.31pm | AQ27: 3.36pm | AR27: 5 | AS27: 5.37pm | AT27: 5.43pm | AU27: 6 | BC27: =IF(AND(G27="Male", J27>25, U27>24.9), "Obese", IF(AND(G27="Female", J27>32, U27>24.9), "Obese", "Not Obese")) -> Not Obese | BE27: CCTV time is in-line with GCR
A28: A025 | B28: 45482 | C28: 2F | D28: 31 | G28: Male | H28: =IF(OR(AND(G28="Male",J28>=25),AND(G28="Female",J28>=32)),"Yes","No") -> No | I28: 65.3 | J28: 19.1 | K28: 7 | L28: 1543 | M28: 33.2 | N28: 38.2 | O28: 27.2 | P28: 50.5 | Q28: 13.3 | R28: 18.2 | S28: 11.6 | T28: 17.7 | U28: 22.1 | V28: 39 | W28: 40 | X28: 38.6 | Y28: =AVERAGE(W28,X28) -> 39.3 | Z28: 46.6 | AA28: 47.5 | AB28: =AVERAGE(Z28,AA28) -> 47.05 | AC28: 46.3 | AD28: 45.1 | AE28: =AVERAGE(AC28,AD28) -> 45.7 | AF28: 12.48pm | AG28: 2.48pm | AH28: 2.54pm | AI28: 4.54pm | AJ28: 5.00pm | AK28: 7.00pm | AM28: 12.48pm | AN28: 7.00pm | AP28: 2.48pm | AQ28: 2.54pm | AR28: 6 | AS28: 4.54pm | AT28: 5.00pm | AU28: 6 | BC28: =IF(AND(G28="Male", J28>25, U28>24.9), "Obese", IF(AND(G28="Female", J28>32, U28>24.9), "Obese", "Not Obese")) -> Not Obese | BE28: CCTV time is in-line with GCR
A29: A026 | B29: 45482 | C29: 3D | D29: 15 | G29: Female | H29: =IF(OR(AND(G29="Male",J29>=25),AND(G29="Female",J29>=32)),"Yes","No") -> Yes | I29: 81.2 | J29: 41.3 | K29: 16 | L29: 1533 | M29: 21.4 | N29: 17.7 | O29: 14.6 | P29: 35.1 | Q29: 38.7 | R29: 55 | S29: 34.4 | T29: 52.5 | U29: 32.7 | V29: 67 | W29: 42.5 | X29: 42.9 | Y29: =AVERAGE(W29,X29) -> 42.7 | Z29: 46.5 | AA29: 46.5 | AB29: =AVERAGE(Z29,AA29) -> 46.5 | AC29: 41.5 | AD29: 41 | AE29: =AVERAGE(AC29,AD29) -> 41.25 | AF29: 12.08pm | AG29: 2.09pm | AH29: 2.16pm | AI29: 4.16pm | AJ29: 4.21pm | AK29: 6.21pm | AL29: 2.16pm - 2.41pm: Motion Sensor Data not saved 2.41pm: Motion Sensor Disconnected. Restarted. 4.42pm: Motion Sensor Stopped. Data Not Saved 6.01pm: 3D_R Disconnected. Lost 7000 points | AM29: 12.08pm | AN29: 6.21pm | AO29: 12.56pm: Adjust Pressure Mat (Back) Frame 2837 2.15pm - 2.16pm: 45 seconds Tekscan Missing (right after Break) 3.17pm: Adjust Pressure Mat (Back) Frame 3615 3.57pm: Adjust Pressure Mat (Back) Frame 5990 5.02pm: 60 seconds Tekscan Missing 6.07pm: Adjust Pressure Mat (Both) Frame 3800 | AP29: 2.09pm | AQ29: 2.14pm | AR29: 5 | AS29: 4.16pm | AT29: 4.21pm | AU29: 5 | BC29: =IF(AND(G29="Male", J29>25, U29>24.9), "Obese", IF(AND(G29="Female", J29>32, U29>24.9), "Obese", "Not Obese")) -> Obese | BE29: CCTV time is in-line with GCR
A30: A027 | B30: 45486 | C30: 2D | D30: 27 | G30: Male | H30: =IF(OR(AND(G30="Male",J30>=25),AND(G30="Female",J30>=32)),"Yes","No") -> No | I30: 59 | J30: 22.2 | K30: 7 | L30: 1421 | M30: 31.1 | N30: 37.6 | O30: 24.8 | P30: 48.5 | Q30: 15.1 | R30: 21.2 | S30: 13.2 | T30: 21 | U30: 21.9 | V30: 38 | W30: 37.2 | X30: 37.4 | Y30: =AVERAGE(W30,X30) -> 37.3 | Z30: 46 | AA30: 46 | AB30: =AVERAGE(Z30,AA30) -> 46 | AC30: 42 | AD30: 42.3 | AE30: =AVERAGE(AC30,AD30) -> 42.15 | AF30: 1.09pm | AG30: 3.10pm | AH30: 3.16pm | AI30: 5.17pm | AJ30: 5.23pm | AK30: 7.23pm | AL30: 2.30pm: 2D_R Stopped 2.47pm - 2.48pm: 2D_R Stopped 3.09pm: 2D_R Stopped 3.37pm: 2D_R Stopped (Lost 12500 Points) 4.57pm: 2D_R Stopped 5.43pm: 2D_R Stopped | AM30: 1.09pm | AN30: 7.23pm | AP30: 3.10pm | AQ30: 3.15pm | AR30: 5 | AS30: 5.17pm | AT30: 5.22pm | AU30: 5 | BB30: 5.24pm: Using Phone 5:45:30 - 5:47:15: Using Phone GCR App Notification Duplicate. Disable Notifications | BC30: =IF(AND(G30="Male", J30>25, U30>24.9), "Obese", IF(AND(G30="Female", J30>32, U30>24.9), "Obese", "Not Obese")) -> Not Obese | BE30: CCTV time is in-line with GCR
A31: A028 | B31: 45486 | C31: 2F | D31: 32 | G31: Female | H31: =IF(OR(AND(G31="Male",J31>=25),AND(G31="Female",J31>=32)),"Yes","No") -> Yes | I31: 78.9 | J31: 32.2 | K31: 9 | L31: 1573 | M31: 28 | N31: 26 | O31: 19.7 | P31: 42.7 | Q31: 31.2 | R31: 41.3 | S31: 26.2 | T31: 37.3 | U31: 28.6 | V31: 54 | W31: 44.4 | X31: 43.8 | Y31: =AVERAGE(W31,X31) -> 44.1 | Z31: 47 | AA31: 46.5 | AB31: =AVERAGE(Z31,AA31) -> 46.75 | AC31: 43.4 | AD31: 42.5 | AE31: =AVERAGE(AC31,AD31) -> 42.95 | AF31: 12.57pm | AG31: 2.58pm | AH31: 3.03pm | AI31: 5.04pm | AJ31: 5.10pm | AK31: 7.10pm | AM31: 12.57pm | AN31: 7.10pm | AP31: 2.58pm | AQ31: 3.03pm | AR31: 5 | AS31: 5.04pm | AT31: 5.10pm | AU31: 6 | BB31: GCR 9th Rating filled 3 mins early (Notifications Duplicate) Disable GCR Notifications | BC31: =IF(AND(G31="Male", J31>25, U31>24.9), "Obese", IF(AND(G31="Female", J31>32, U31>24.9), "Obese", "Not Obese")) -> Obese | BE31: CCTV time is in-line with GCR
A32: A029 | B32: 45486 | C32: 3D | D32: 27 | G32: Female | H32: =IF(OR(AND(G32="Male",J32>=25),AND(G32="Female",J32>=32)),"Yes","No") -> Yes | I32: 56.2 | J32: 32 | K32: 5 | L32: 1203 | M32: 24.5 | N32: 26.8 | O32: 18.9 | P32: 36.5 | Q32: 26.2 | R32: 43.1 | S32: 22.9 | T32: 36.3 | U32: 22 | V32: 51 | W32: 34.5 | X32: 34.6 | Y32: =AVERAGE(W32,X32) -> 34.55 | Z32: 46.5 | AA32: 45.9 | AB32: =AVERAGE(Z32,AA32) -> 46.2 | AC32: 41.5 | AD32: 42.4 | AE32: =AVERAGE(AC32,AD32) -> 41.95 | AF32: 12.38pm | AG32: 2.41pm | AH32: 2.46pm | AI32: 4.48pm | AJ32: 4.54pm | AK32: 6.55pm | AL32: 4.26pm: 3D_L Stopped | AM32: 12.42pm | AN32: 6.55pm | AO32: 1.02pm - 1.03pm: Restarted Tekscan Tekscan Disconnected during 2nd Toilet Break. No Data Missed 5.34pm - 5.35pm: Restarted Tekscan | AP32: 2.41pm | AQ32: 2.46pm | AR32: 5 | AS32: 4.48pm | AT32: 4.53pm | AU32: 5 | BB32: Tekscan has been delayed by 1 min 37 seconds | BC32: =IF(AND(G32="Male", J32>25, U32>24.9), "Obese", IF(AND(G32="Female", J32>32, U32>24.9), "Obese", "Not Obese")) -> Not Obese | BE32: CCTV time is in-line with GCR
A33: A030 | B33: 45486 | C33: 3F | D33: 31 | G33: Female | H33: =IF(OR(AND(G33="Male",J33>=25),AND(G33="Female",J33>=32)),"Yes","No") -> No | I33: 48.5 | J33: 26.9 | K33: 1.5 | L33: 1102 | M33: 26.1 | N33: 30.4 | O33: 20.8 | P33: 38.1 | Q33: 21 | R33: 36.9 | S33: 17.6 | T33: 29.3 | U33: 18.3 | V33: 44 | W33: 36.8 | X33: 36.2 | Y33: =AVERAGE(W33,X33) -> 36.5 | Z33: 45 | AA33: 45 | AB33: =AVERAGE(Z33,AA33) -> 45 | AC33: 45 | AD33: 44.7 | AE33: =AVERAGE(AC33,AD33) -> 44.85 | AF33: 12.24pm | AG33: 2.26pm | AH33: 2.33pm | AI33: 4.34pm | AJ33: 4.40pm | AK33: 6.44pm | AM33: 12.30pm | AN33: 6.44pm | AO33: 3.32pm: Adjust Pressure Mat (Seat) Frame 10750 | AP33: 2.26pm | AQ33: 2.33pm | AR33: 7 | AS33: 4.34pm | AT33: 4.40pm | AU33: 6 | BB33: 2.34pm - 3.00pm: GoPro Not Recording Tekscan has been delayed by 4 mins 42 seconds | BC33: =IF(AND(G33="Male", J33>25, U33>24.9), "Obese", IF(AND(G33="Female", J33>32, U33>24.9), "Obese", "Not Obese")) -> Not Obese | BE33: CCTV time is in-line with GCR
A34: A031 | B34: 45488 | C34: 2F | D34: 32 | E34: 34 | F34: 36 | G34: Male | H34: =IF(OR(AND(G34="Male",J34>=25),AND(G34="Female",J34>=32)),"Yes","No") -> Yes | I34: 86.8 | J34: 29 | K34: 17 | L34: 1834 | M34: 29.2 | N34: 34.5 | O34: 21.4 | P34: 46.6 | Q34: 20.5 | R34: 25.6 | S34: 18.8 | T34: 26.1 | U34: 29 | V34: 62 | W34: 43.4 | X34: 42.6 | Y34: =AVERAGE(W34,X34) -> 43 | Z34: 49 | AA34: 50 | AB34: =AVERAGE(Z34,AA34) -> 49.5 | AC34: 48.7 | AD34: 49 | AE34: =AVERAGE(AC34,AD34) -> 48.85 | AF34: 12.45pm | AG34: 2.46pm | AH34: 2.51pm | AI34: 4.52pm | AJ34: 4.58pm | AM34: 12.45pm | AP34: 2.46pm | AQ34: 2.51pm | AR34: 5 | AS34: 4.52pm | AT34: 4.57pm | AU34: 5 | BC34: =IF(AND(G34="Male", J34>25, U34>24.9), "Obese", IF(AND(G34="Female", J34>32, U34>24.9), "Obese", "Not Obese")) -> Obese | BE34: CCTV time is 1 second early; CCTV time: 14:46:35 GCR filled at 14:46:36
A35: A032 | B35: 45488 | C35: 3D | D35: 20 | G35: Female | H35: =IF(OR(AND(G35="Male",J35>=25),AND(G35="Female",J35>=32)),"Yes","No") -> No | I35: 58.8 | J35: 29.4 | K35: 4 | L35: 1258 | M35: 26.2 | N35: 28.3 | O35: 20.2 | P35: 39 | Q35: 24.7 | R35: 39.8 | S35: 21 | T35: 33.5 | U35: 21.6 | V35: 49 | W35: 41.1 | X35: 40.8 | Y35: =AVERAGE(W35,X35) -> 40.95 | Z35: 45.1 | AA35: 44.5 | AB35: =AVERAGE(Z35,AA35) -> 44.8 | AC35: 44.2 | AD35: 44 | AE35: =AVERAGE(AC35,AD35) -> 44.1 | AF35: 12.30pm | AG35: 2.31pm | AH35: 2.37pm | AI35: 4.38pm | AJ35: 4.44pm | AL35: 3D_R Stopped (missing about 8000 points in S2 1602: 3D_L Stopped | AM35: 12.31pm | AP35: 2.31pm | AQ35: 2.36pm | AR35: 5 | AS35: 4.38pm | AT35: 4.44pm | AU35: 6 | BB35: 12.36pm: Using Phone 1310: Leans forward to touch screen (while filling in ratings) 13:12:00 - 13:12:15 - Turns to put remote 1332 - 1335: Toilet (Frame 3790) Frame 6530 - 6575: Turn Left to pick up bottle and tissue 1438 - 14:39:30 - Use Phone (Right after 1st break) 1519 - 1522: Toilet 1824: Sneezing / Coughing for 1 min approx. | BC35: =IF(AND(G35="Male", J35>25, U35>24.9), "Obese", IF(AND(G35="Female", J35>32, U35>24.9), "Obese", "Not Obese")) -> Not Obese | BE35: CCTV time is 1 second early; CCTV time: 16:38:44 GCR filled at 16:38:45
A36: A033 | B36: 45489 | C36: 2D | D36: 24 | G36: Female | H36: =IF(OR(AND(G36="Male",J36>=25),AND(G36="Female",J36>=32)),"Yes","No") -> No | I36: 48.7 | J36: 26.9 | K36: 2 | L36: 1105 | M36: 26.1 | N36: 30.3 | O36: 20.8 | P36: 38.3 | Q36: 21.5 | R36: 36.9 | S36: 18 | T36: 30 | U36: 19 | V36: 43 | W36: 38.2 | X36: 36.8 | Y36: =AVERAGE(W36,X36) -> 37.5 | Z36: 44 | AA36: 42.7 | AB36: =AVERAGE(Z36,AA36) -> 43.35 | AC36: 43.3 | AD36: 43 | AE36: =AVERAGE(AC36,AD36) -> 43.15 | AF36: 12.40pm | AG36: 2.43pm | AH36: 2.48pm | AI36: 4.49pm | AJ36: 4.54pm | AK36: 6.55pm | AL36: 1.01pm: Motion Sensors Disconnected (5000 points lost) 3.28pm: Motion Sensors Disconnected 4.28pm: 2D_R Disconnected 5.54pm: 2D_R Disconnected 6.14pm: Motion Sensor App Crash 6.19pm: 2D_R Disconnected 6.34pm: 2D_R Disconnected | AM36: 12.41pm | AN36: 6.55pm | AP36: 2.43pm | AQ36: 2.48pm | AR36: 5 | AS36: 4.49pm | AT36: 4.54pm | AU36: 5 | BC36: =IF(AND(G36="Male", J36>25, U36>24.9), "Obese", IF(AND(G36="Female", J36>32, U36>24.9), "Obese", "Not Obese")) -> Not Obese | BE36: CCTV time is in-line with GCR
A37: A034 | B37: 45489 | C37: 2F | D37: 32 | G37: Female | H37: =IF(OR(AND(G37="Male",J37>=25),AND(G37="Female",J37>=32)),"Yes","No") -> No | I37: 56.3 | J37: 30.9 | K37: 7 | L37: 1209 | M37: 25 | N37: 27.3 | O37: 18.8 | P37: 38.5 | Q37: 27.4 | R37: 40.7 | S37: 23.3 | T37: 35 | U37: 24.4 | V37: 56 | W37: 38.9 | X37: 39.8 | Y37: =AVERAGE(W37,X37) -> 39.35 | Z37: 43.4 | AA37: 43.2 | AB37: =AVERAGE(Z37,AA37) -> 43.3 | AC37: 39.1 | AD37: 39.1 | AE37: =AVERAGE(AC37,AD37) -> 39.1 | AF37: 12.49pm | AG37: 2.51pm | AH37: 2.56pm | AI37: 4.57pm | AJ37: 5.02pm | AK37: 7.02pm | AM37: 12.49pm | AN37: 7.03pm | AP37: 2.51pm | AQ37: 2.56pm | AR37: 5 | AS37: 4.57pm | AT37: 5.02pm | AU37: 5 | BB37: Disable GCR App Notifications, missing minicam footage (unable to find from 2F sd card) | BC37: =IF(AND(G37="Male", J37>25, U37>24.9), "Obese", IF(AND(G37="Female", J37>32, U37>24.9), "Obese", "Not Obese")) -> Not Obese | BE37: CCTV time is in-line with GCR
A38: A035 | B38: 45489 | C38: 3D | D38: 16 | G38: Male | H38: =IF(OR(AND(G38="Male",J38>=25),AND(G38="Female",J38>=32)),"Yes","No") -> No | I38: 77.4 | J38: 24.4 | K38: 9.5 | L38: 1718 | M38: 31.9 | N38: 36.8 | O38: 24.7 | P38: 49.2 | Q38: 16.9 | R38: 23.1 | S38: 15.1 | T38: 23 | U38: 24.4 | V38: 46 | W38: 40.8 | X38: 39.3 | Y38: =AVERAGE(W38,X38) -> 40.05 | Z38: 50.6 | AA38: 51.7 | AB38: =AVERAGE(Z38,AA38) -> 51.15 | AC38: 50 | AD38: 50.1 | AE38: =AVERAGE(AC38,AD38) -> 50.05 | AF38: 12.52pm | AG38: 2.52pm | AH38: 2.57pm | AI38: 4.57pm | AJ38: 5.02pm | AK38: 7.03pm | AL38: 1.31pm: 3D_L Disconnected 5.22pm: 3D_L Disconnected 6.02pm: Motion Sensors Disconnected 6.22pm: Motion Sensors Disconnected 7.02pm: 3D_L Disconnected | AM38: 12.52pm | AN38: 7.04pm | AP38: 2.52pm | AQ38: 2.57pm | AR38: 5 | AS38: 4.57pm | AT38: 5.02pm | AU38: 5 | BB38: 4:07:30pm - 4.08pm: Moved to grab item from bag 4.51pm: Subject Fidgeting with Pen (Pen Clicking) 5.45pm: CCTV Recording Restarted 6.42pm: Subject Open Seat Table | BC38: =IF(AND(G38="Male", J38>25, U38>24.9), "Obese", IF(AND(G38="Female", J38>32, U38>24.9), "Obese", "Not Obese")) -> Not Obese | BE38: CCTV time is in-line with GCR
A39: A036 | B39: 45489 | C39: 3F | D39: 30 | G39: Female | H39: =IF(OR(AND(G39="Male",J39>=25),AND(G39="Female",J39>=32)),"Yes","No") -> No | I39: 57.2 | J39: 29.2 | K39: 4.5 | L39: 1233 | M39: 26.1 | N39: 28.5 | O39: 20.2 | P39: 39.4 | Q39: 25.3 | R39: 39.4 | S39: 21.3 | T39: 33.8 | U39: 22.6 | V39: 49 | W39: 38.8 | X39: 37.8 | Y39: =AVERAGE(W39,X39) -> 38.3 | Z39: 44.4 | AA39: 44.9 | AB39: =AVERAGE(Z39,AA39) -> 44.65 | AC39: 41.8 | AD39: 42.3 | AE39: =AVERAGE(AC39,AD39) -> 42.05 | AF39: 12.31pm | AG39: 2.29pm | AH39: 2.35pm | AI39: 4.35pm | AJ39: 4.42pm | AK39: 6.43pm | AL39: 12.28pm - 12.31pm: Motion Sensor App Crash. Data Loss 3.36pm: Motion Sensors Disconnected 5.23pm: 3F_L Disconnected 6.42pm: 3F_L Disconnected | AM39: 12.27pm | AN39: 6.44pm | AP39: 2.29pm | AQ39: 2.35pm | AR39: 6 | AS39: 4.36pm | AT39: 4.42pm | AU39: 6 | BB39: 5.45pm: CCTV Recording Restarted 5.55pm: Disable GCR App Notifications | BC39: =IF(AND(G39="Male", J39>25, U39>24.9), "Obese", IF(AND(G39="Female", J39>32, U39>24.9), "Obese", "Not Obese")) -> Not Obese | BE39: CCTV time is in-line with GCR
A40: A037 | B40: 45510 | C40: 2D | D40: 25 | G40: Female | H40: =IF(OR(AND(G40="Male",J40>=25),AND(G40="Female",J40>=32)),"Yes","No") -> Yes | I40: 54 | J40: 34.9 | K40: 7 | L40: 1154 | M40: 22.4 | N40: 24.9 | O40: 17 | P40: 35.1 | Q40: 29.1 | R40: 46.3 | S40: 25.9 | T40: 39.5 | U40: 24 | V40: 56 | W40: 37 | X40: 37.9 | Y40: =AVERAGE(W40,X40) -> 37.45 | Z40: 44.6 | AA40: 44.7 | AB40: =AVERAGE(Z40,AA40) -> 44.65 | AC40: 43.6 | AD40: 43.6 | AE40: =AVERAGE(AC40,AD40) -> 43.6 | AF40: 12.48pm | AG40: 2.49pm | AH40: 2.56pm | AI40: 4.57pm | AJ40: 5.02pm | AK40: 7.03pm | AL40: 1.30pm: 2D_R Disconnected 1.50pm: 2D_L Disconnected 4.17pm: Both Disconnected 5.24pm: Both Disconnected 6.02pm: 2D_R Disconnected 6.23pm: 2D_R Disconnected 6.42pm: Both Disconnected | AM40: 12.49pm | AN40: 7.03pm | AP40: 2.50pm | AQ40: 2.55pm | AR40: 5 | AS40: 4.57pm | AT40: 5.02pm | AU40: 5 | BB40: Extra Entry at 5.17pm - Disable App Notification 6:23:30 => Lean Forward to talk to researcher 6:43:30 => Movements to talk to researcher | BC40: =IF(AND(G40="Male", J40>25, U40>24.9), "Obese", IF(AND(G40="Female", J40>32, U40>24.9), "Obese", "Not Obese")) -> Not Obese | BE40: CCTV time is in-line with GCR
...

Sheet Pre-Q
A1: Subject code | B1: Selected | D1: Please enter your name. | E1: Sex: | F1: Height (in cm): | G1: Weight (in kg): | H1: Age (in years): | I1: Nationality: | J1: Ethnicity | K1: Where did you hear about the study? | L1: Are you currently feeling any muscle fatigue or soreness at any regions of your body? | M1: If Yes, which body region? | N1: Have you travelled across more than 1 time zone in the last 3 weeks? | O1: If yes, where to? | P1: How many flights have you taken in the past year? | Q1: In your previous flights, which class did you most frequently travel in? | R1: Have you ever taken a Business Class flight before? | S1: How many years have you been flying SIA Business Class on a regular basis? | T1: How many Business Class flights have you taken in the past 6 months? | U1: When was your most recent SIA Business Class flight? (strictly SIA) | V1: When was your most recent non-SIA Business Class flight? | W1: How frequently do you take long-haul (6-12 hours) or ultra-long-haul (more than 12 hours) flights a year? | X1: In your most recent flight, did you feel discomfort at any point during the flight? | Y1: If Yes, what do you think was the main cause of discomfort? | Z1: What is your typical daily duration of sitting? (i.e., At work or at home) | AA1: Do you often experience discomfort while sitting for an extended period?
A2: A005 | B2: 1 | C2: Ng Guat Ping | D2: Guat Ping Ng | E2: Female | F2: 161 | G2: 70 | H2: 50 | I2: Singapore Citizen | J2: Chinese | K2: Word of mouth | L2: No | N2: No | P2: 1 to 5 | Q2: Economy Class | R2: Yes | S2: 15 | T2: 0 | W2: 1 to 5 | X2: No | Z2: 6 to 9 hours | AA2: Yes
A3: A008 | B3: 1 | C3: Viknesvaran Selvarajan | D3: Viknesvaran Selvarajan | E3: Male | F3: 178 | G3: 73 | H3: 44 | I3: Malaysian | J3: Indian | K3: Telegram | L3: No | N3: No | P3: 1 to 5 | Q3: Economy Class | R3: No | W3: 1 to 5 | X3: No | Z3: 3 to 6 hours | AA3: No
A4: A009 | B4: 1 | C4: Umathevy Janarthanan | D4: Umathevy Janarthanan | E4: Female | F4: 156 | G4: 60 | H4: 42 | I4: Malaysian | J4: Indian | K4: Telegram | L4: No | N4: No | P4: 1 to 5 | Q4: Economy Class | R4: No | W4: 1 to 5 | X4: No | Z4: 3 to 6 hours | AA4: No
A5: A012 | B5: 1 | C5: KANG POH SENG | D5: KANG POH SENG | E5: Male | F5: 162 | G5: 70 | H5: 54 | I5: Singapore | J5: Chinese | K5: Friend | L5: No | N5: No | P5: 1 to 5 | Q5: Economy Class | R5: No | W5: 1 to 5 | X5: No | Z5: 3 to 6 hours | AA5: No
A6: A020 | B6: 1 | C6: Fiona Loke | D6: Loke Yean Nee Fiona | E6: Female | F6: 157 | G6: 75 | H6: 49 | I6: Singaporean | J6: Chinese | K6: My Dad | L6: No | N6: No | P6: 1 to 5 | Q6: Economy Class | R6: No | W6: 6 to 15 | X6: Yes | Y6: Seat cushion and lowering of the seat | Z6: 0 to 3 hours | AA6: Yes
A7: A021 | B7: 1 | C7: Alyn Wong | D7: Alyn Wong | E7: Female | F7: 160 | G7: 45 | H7: 54 | I7: Singapore Citizen | J7: Chinese | K7: Friend | L7: No | N7: No | P7: 0 | Q7: Economy Class | R7: No | W7: 0 | X7: No | Z7: 3 to 6 hours | AA7: No
A8: A023 | B8: 1 | C8: Toh Ee Wen Kelvin | D8: Toh Ee Wen Kelvin | E8: Male | F8: 178 | G8: 108 | H8: 41 | I8: Singapore | J8: Chinese | K8: Telegram | L8: No | N8: No | P8: 1 to 5 | Q8: Economy Class | R8: Yes | S8: 0 | T8: 0 | W8: 1 to 5 | X8: No | Z8: More than 9 hours | AA8: Yes
A9: A027 | B9: 1 | C9: Eugene Chen | D9: Eugene Chen | E9: Male | F9: 164 | G9: 59 | H9: 43 | I9: Singaporean | J9: Chinese | K9: Telegram | L9: No | N9: No | P9: 1 to 5 | Q9: Economy Class | R9: Yes | T9: 0 | W9: 1 to 5 | X9: No | Z9: More than 9 hours | AA9: No
A10: A029 | B10: 1 | C10: Ng Choon Bee | D10: Ng Choon Bee | E10: Female | F10: 160 | G10: 54 | H10: 51 | I10: Singaporean | J10: Chinese | K10: Family | L10: No | N10: No | P10: 1 to 5 | Q10: Economy Class | R10: Yes | S10: O | T10: 0 | W10: 1 to 5 | X10: Yes | Y10: Inability to sleep well | Z10: 3 to 6 hours | AA10: No
A11: A030 | B11: 1 | C11: CHOW KIT YEE | D11: CHOW KIT YEE | E11: Female | F11: 163 | G11: 50 | H11: 58 | I11: Singaporean | J11: Chinese | K11: Friend | L11: No | N11: No | P11: 1 to 5 | Q11: Economy Class | R11: No | W11: 1 to 5 | X11: Yes | Y11: Space constraint | Z11: 6 to 9 hours | AA11: Yes
A12: A031 | B12: 1 | C12: John Lim | D12: John Lim | E12: Male | F12: 1.73 | G12: 80 | H12: 55 | I12: Singapore | J12: Chinese | K12: edm | L12: No | N12: No | P12: 1 to 5 | Q12: Economy Class | R12: Yes | S12: 1 | T12: 0 | W12: 0 | X12: No | Z12: 6 to 9 hours | AA12: No
A13: A034 | B13: 1 | C13: Ng Beng See | D13: Ng Beng See | E13: Female | F13: 152 | G13: 56 | H13: 55 | I13: Singapore | J13: Chinese | K13: friend | L13: No | N13: No | P13: 1 to 5 | Q13: Economy Class | R13: No | W13: 1 to 5 | X13: Yes | Y13: seated too long, narrow seat | Z13: 0 to 3 hours | AA13: Yes
A14: A039 | B14: 1 | C14: YAP SIEW LING ROSALIND | D14: Yap Siew Ling Rosalind | E14: Female | F14: 163 | G14: 63 | H14: 55 | I14: Singaporean | J14: Chinese | K14: Friend | L14: No | N14: No | P14: 1 to 5 | Q14: Economy Class | R14: Yes | T14: 0 | W14: 1 to 5 | X14: Yes | Y14: Cabin temperature is warm. Seating discomfort near end of flight. | Z14: 3 to 6 hours | AA14: Yes
A15: A047 | B15: 1 | C15: Tan Hui Soon | D15: Tan hui soon | E15: Female | F15: 166 | G15: 59 | H15: 54 | I15: Singaporean | J15: Chinese | K15: Friend | L15: No | N15: No | P15: 1 to 5 | Q15: Economy Class | R15: Yes | S15: 7 | T15: 0 | W15: 1 to 5 | X15: Yes | Y15: Tight leg space and seat, turbulence, dry air | Z15: 0 to 3 hours | AA15: Yes
A16: A048 | B16: 1 | C16: NORFARTINA ABDUL HAMID | D16: NORFARTINA BINTE ABDUL HAMID | E16: Female | F16: 149 | G16: 64 | H16: 42 | I16: SINGAPOREAN | J16: Malay | K16: A FRIEND SHARE IT FROM TELEGRAM | L16: No | N16: No | P16: 6 to 15 | Q16: Economy Class | R16: No | W16: 0 | X16: No | Z16: 3 to 6 hours | AA16: Yes
A17: A050 | B17: 1 | C17: Yee Hsien Ta | D17: Jason Yee | E17: Male | F17: 170 | G17: 68 | H17: 55 | I17: Singaporean | J17: Chinese | K17: From friends | L17: No | N17: No | P17: 1 to 5 | Q17: Premium Economy Class | R17: Yes | S17: 1 | T17: 0 | W17: 1 to 5 | X17: No | Z17: More than 9 hours | AA17: No
A18: A052 | B18: 1 | C18: Yvonne Lim | D18: Yvonne Kek | E18: Female | F18: 159 | G18: 47 | H18: 52 | I18: Singaporean | J18: Chinese | K18: Friend | L18: No | N18: No | P18: 0 | Q18: Economy Class | R18: No | W18: 0 | X18: No | Z18: 3 to 6 hours | AA18: No
A19: A053 | B19: 1 | C19: Davis Sim Kok Hiang | D19: Davis Sim Kok Hiang | E19: Male | F19: 176 | G19: 107 | H19: 42 | I19: Singaporean | J19: Chinese | K19: telegram | L19: No | N19: No | P19: 1 to 5 | Q19: Economy Class | R19: Yes | T19: 1 to 5 | U19: More than 6 months ago | V19: More than 6 months ago | W19: 1 to 5 | X19: Yes | Y19: overnight flight and seat size. | Z19: More than 9 hours | AA19: Yes
A20: A058 | B20: 1 | C20: Chua Chek Meng | D20: Eddie Chua | E20: Male | F20: 171 | G20: 79 | H20: 59 | I20: Singapore | J20: Chinese | K20: Friends | L20: No | N20: No | P20: 6 to 15 | Q20: Economy Class | R20: Yes | S20: 2 | T20: 0 | W20: 1 to 5 | X20: Yes | Y20: Stay in the seat for long hours | Z20: 6 to 9 hours | AA20: No
A21: A060 | B21: 1 | C21: ong bee yong | D21: Ong Bee Yong | E21: Female | F21: 156 | G21: 60 | H21: 50 | I21: Singaporean | J21: Chinese | K21: Friend | L21: No | N21: No | P21: 1 to 5 | Q21: Economy Class | R21: Yes | S21: Nil | T21: 0 | W21: 1 to 5 | X21: Yes | Y21: The back of the seat causes back aches - not comfortable, n the size of the seat. | Z21: 3 to 6 hours | AA21: Yes
A22: A063 | B22: 1 | C22: Koay siew hoon | D22: Sandy | E22: Female | F22: 150 | G22: 46.5 | H22: 44 | I22: Singaporean | J22: Chinese | K22: From friend | L22: No | N22: No | P22: 1 to 5 | Q22: Economy Class | R22: No | W22: 6 to 15 | X22: No | Z22: 3 to 6 hours | AA22: Yes
A23: A068 | B23: 1 | C23: Cheng Zhe | D23: Cheng Zhe | E23: Male | F23: 171 | G23: 76 | H23: 48 | I23: Singaporean | J23: Chinese | K23: Friend | L23: No | N23: No | P23: 1 to 5 | Q23: Economy Class | R23: No | W23: 1 to 5 | X23: No | Z23: 6 to 9 hours | AA23: No
A24: A077 | B24: 1 | C24: Hartaty Widjaja | D24: Hartaty Widjaja | E24: Female | F24: 155 | G24: 58 | H24: 63 | I24: Indonesian | J24: Chinese | K24: Friend | L24: No | N24: No | P24: 6 to 15 | Q24: Economy Class | R24: Yes | T24: 0 | W24: 1 to 5 | X24: Yes | Y24: No comfortable place to rest my head | Z24: 3 to 6 hours | AA24: No
A25: A078 | B25: 1 | C25: Adeline Heng | D25: Adeline Heng | E25: Female | F25: 167 | G25: 64 | H25: 57 | I25: Singaporean | J25: Chinese | K25: A friend | L25: Yes | M25: Right Shoulder | N25: No | P25: 0 | Q25: Economy Class | R25: Yes | S25: Once only | T25: 0 | W25: 0 | X25: No | Z25: 0 to 3 hours | AA25: No
A26: A087 | B26: 1 | C26: Mark Chen | D26: Mark Chen | E26: Male | F26: 179 | G26: 65 | H26: 42 | I26: Sgrean | J26: Chinese | K26: From a friend | L26: No | N26: No | P26: 6 to 15 | Q26: Economy Class | R26: Yes | S26: 0 | T26: 0 | W26: 1 to 5 | X26: Yes | Y26: Leg soreness | Z26: 6 to 9 hours | AA26: No
A27: A088 | B27: 1 | C27: Seow cherng jye | D27: Seow Cherng jye | E27: Male | F27: 175 | G27: 76 | H27: 43 | I27: Singaporean | J27: Chinese | K27: From friend | L27: No | N27: No | P27: 6 to 15 | Q27: Economy Class | R27: Yes | S27: 0 | T27: 0 | W27: 1 to 5 | X27: Yes | Y27: Back and neck stiffness | Z27: 3 to 6 hours | AA27: No
A28: A091 | B28: 1 | C28: Valerie Eng Li Huay | D28: Valerie Eng Li Huay | E28: Female | F28: 163 | G28: 55 | H28: 51 | I28: Singaporean | J28: Chinese | K28: Friend | L28: No | N28: No | P28: More than 15 | Q28: Economy Class | R28: Yes | T28: 0 | W28: 0 | X28: No | Z28: 0 to 3 hours | AA28: Yes
A29: A092 | B29: 1 | C29: Peh Ai Ling Irene | D29: Peh Ai Ling Irene | E29: Female | F29: 156 | G29: 47 | H29: 48 | I29: Singaporean | J29: Chinese | K29: Friend | L29: No | N29: No | P29: 1 to 5 | Q29: Economy Class | R29: No | W29: 6 to 15 | X29: No | Z29: 0 to 3 hours | AA29: No
A30: A096 | B30: 1 | C30: Hoong Suet Lee | D30: Hoong Suet Lee | E30: Female | F30: 164 | G30: 65 | H30: 59 | I30: Singaporean | J30: Chinese | K30: Friend | L30: No | N30: No | P30: 1 to 5 | Q30: Economy Class | R30: No | W30: 1 to 5 | X30: No | Z30: 3 to 6 hours | AA30: No
A31: A099 | B31: 1 | C31: Claire Teo | D31: Claire Teo | E31: Female | F31: 166 | G31: 82 | H31: 42 | I31: SINGAPOREAN | J31: Chinese | K31: Telegram | L31: No | N31: No | P31: 1 to 5 | Q31: Economy Class | R31: Yes | T31: 0 | W31: 0 | X31: Yes | Y31: Uncomfortable due to restricted chair position | Z31: 6 to 9 hours | AA31: Yes
A32: A102 | B32: 1 | C32: Ng Siew Hwa | D32: Ng Siew Hwa | E32: Female | F32: 148 | G32: 45 | H32: 63 | I32: Singapore | J32: Chinese | K32: Friend | L32: No | N32: No | P32: 1 to 5 | Q32: Economy Class | R32: Yes | T32: 0 | W32: 1 to 5 | X32: No | Z32: 3 to 6 hours | AA32: No
A33: A103 | B33: 1 | C33: Susanna Lam | D33: Susanna Lam | E33: Female | F33: 1.62 | G33: 65 | H33: 62 | I33: Singaporean | J33: Chinese | K33: Friend | L33: No | N33: No | P33: More than 15 | Q33: Business Class | R33: Yes | S33: 3 years | T33: 0 | W33: 1 to 5 | X33: No | Z33: 6 to 9 hours | AA33: Yes
A34: A107 | B34: 1 | C34: Lee Kian Wee | D34: Lee Kian Wee | E34: Male | F34: 180 | G34: 79 | H34: 54 | I34: Singaporean | J34: Chinese | K34: Friend | L34: No | N34: No | P34: 1 to 5 | Q34: Economy Class | R34: Yes | S34: 0 | T34: 0 | W34: 1 to 5 | X34: Yes | Y34: Seat | Z34: 3 to 6 hours | AA34: Yes
A35: A108 | B35: 1 | C35: Frances Koo | D35: Frances Koo | E35: Female | F35: 165 | G35: 70 | H35: 55 | I35: Singaporean | J35: Chinese | K35: From a friend | L35: No | N35: No | P35: 1 to 5 | Q35: Economy Class | R35: No | W35: 1 to 5 | X35: Yes | Y35: The seat | Z35: 6 to 9 hours | AA35: No
A36: A109 | B36: 1 | C36: Soeapi Soelaiman | D36: Soeapi Soelaiman | E36: Male | F36: 168 | G36: 70 | H36: 53 | I36: Indonesian | J36: Chinese | K36: Friends | L36: No | N36: No | P36: 6 to 15 | Q36: Economy Class | R36: Yes | S36: 2 | T36: 0 | W36: 1 to 5 | X36: Yes | Y36: Seat and leg space | Z36: 3 to 6 hours | AA36: No
A37: A113 | B37: 1 | C37: Ho Cheun Yin | D37: HO CHEUN YIN | E37: Male | F37: 169 | G37: 60 | H37: 53 | I37: SINGAPOREAN | J37: Chinese | K37: From my wife | L37: No | N37: No | P37: 1 to 5 | Q37: Economy Class | R37: No | W37: 0 | X37: No | Z37: 0 to 3 hours | AA37: Yes
A38: A114 | B38: 1 | C38: Tong Sook Yeen | D38: Tong Sook Yeen | E38: Female | F38: 160 | G38: 63 | H38: 51 | I38: Singaporean | J38: Chinese | K38: Friend | L38: No | N38: No | P38: 1 to 5 | Q38: Economy Class | R38: No | W38: 0 | X38: No | Z38: 3 to 6 hours | AA38: Yes
A39: A118 | B39: 1 | C39: Lam Woon Chin | D39: Lam Woon Chin | E39: Female | F39: 159 | G39: too heavy | H39: 50 | I39: Singaporean | J39: Chinese | K39: Friend | L39: No | N39: No | P39: 6 to 15 | Q39: Economy Class | R39: No | W39: 1 to 5 | X39: No | Z39: 3 to 6 hours | AA39: Yes
A40: A121 | B40: 1 | C40: Camelia Chng | D40: Camelia Chng | E40: Female | F40: 152 | G40: 50 | H40: 59 | I40: Singaporean | J40: Chinese | K40: Friends | L40: No | N40: No | P40: 1 to 5 | Q40: Economy Class | R40: No | W40: 1 to 5 | X40: Yes | Y40: Sitting in one position for too long. | Z40: 6 to 9 hours | AA40: Yes
...

Sheet Post-Q
A1: Finished | B1: Subject Code | D1: Please enter your name. | E1: Please rate your overall discomfort experience during the study. | F1: What factors affected your overall discomfort experience during the study? | G1: Were there any issues with recording your discomfort ratings during the flight study? | H1: Were there any issues when watching the In-flight Entertainment? | I1: Please select other forms of discomfort that you experienced during the study. Check all that apply. - Selected Choice | J1: Please select other forms of discomfort that you experienced during the study. Check all that apply. - Others (please specify): - Text | K1: Seat dimensions | L1: Seat cushion | M1: Seat recline | N1: Footwell (space for the feet at the front of the seat) | O1: Leg rest (part of the seat that supports the calves) | P1: Headrest | Q1: Armrest | R1: Are there other aspects of the seat that are important to you? | S1: Are there any additional factors that could be addressed to help reduce your discomfort experienced?
A2: TRUE | B2: A001 | C2: Markus Labude | D2: Markus Labude | E2: Slight discomfort | F2: The light and noise | G2: No | H2: No | I2: Others (please specify): | J2: Not much except the light | K2: 7 | L2: 6 | M2: 1 | N2: 5 | O2: 2 | P2: 3 | Q2: 4 | R2: No | S2: No
A3: TRUE | B3: A002 | C3: Gerry Gewi Kwok Wei | D3: Gerry Gewi Kwok wei | E3: Slight discomfort | F3: Inability to use leg rest; small and non-adjustable screen | G3: No | H3: No | I3: Restricted space for movement,Seat angle | K3: 1 | L3: 3 | M3: 2 | N3: 4 | O3: 5 | P3: 7 | Q3: 6 | R3: No | S3: Better arm rest. Too low on my right, too high on my left
A4: TRUE | B4: A003 | C4: SEETHA | D4: Seetha | E4: Slight discomfort | F4: No. It was quite pleasant. | G4: No. | H4: No. Netflix is great. | I4: Others (please specify): | J4: Headrest not adjustable. | K4: 3 | L4: 4 | M4: 1 | N4: 7 | O4: 6 | P4: 2 | Q4: 5 | R4: No. | S4: No.
A5: TRUE | B5: A004 | C5: Isabel lim | D5: Isabel Lim shin ping | E5: Slight discomfort | F5: The chair position | G5: No at all | H5: The survey disruption if not is better | I5: Seat angle | K5: 5 | L5: 6 | M5: 1 | N5: 2 | O5: 7 | P5: 4 | Q5: 3 | R5: No | S5: Recline more
A6: TRUE | B6: A005 | C6: Ng Guat Ping | D6: Guat Ping Ng | E6: Slight discomfort | F6: Not being able to move around and fighting off the urge to sleep. | G6: No | H6: No | I6: Seat angle,Others (please specify): | J6: Wanted to change the seat angle to be more upright after being in the same position for some time. | K6: 5 | L6: 2 | M6: 1 | N6: 4 | O6: 6 | P6: 3 | Q6: 7 | R6: No | S6: Something to hug would help
A7: TRUE | B7: A006 | C7: Chow Kit Seen | D7: Chow Kit Seen | E7: Moderate discomfort | F7: Weak back and long hours sitting | G7: No | H7: No | I7: Seat angle | K7: 1 | L7: 2 | M7: 3 | N7: 5 | O7: 6 | P7: 4 | Q7: 7 | R7: Nil | S7: Able to get up and stretch
A8: TRUE | B8: A007 | C8: Ian Zeng | D8: Ian Zeng | E8: Slight discomfort | F8: Angle of seat (lateral) | G8: No | H8: Slight difficulty in navigating Netflix | K8: 6 | L8: 3 | M8: 5 | N8: 1 | O8: 4 | P8: 7 | Q8: 2 | R8: Alignment of Center of seat and left armrest | S8: The positioning of the inflight entertainment with respect to the seat. I had to lean left to view the screen, resulting in my bum being numb
A9: TRUE | B9: A008 | C9: Viknesvaran Selvarajan | D9: Viknesvaran Selvarajan | E9: Moderate discomfort | F9: Less area to stretch the legs. | G9: No | H9: No | I9: Restricted space for movement | K9: 5 | L9: 2 | M9: 4 | N9: 1 | O9: 3 | P9: 6 | Q9: 7 | R9: Seat material. | S9: Provide sufficient space for movement.
A10: TRUE | B10: A009 | C10: Umathevy Janarthanan | D10: Umathevy Janarthanan | E10: Slight discomfort | F10: Sitting too long. | G10: No | H10: No | I10: Restricted space for movement | K10: 4 | L10: 1 | M10: 3 | N10: 7 | O10: 6 | P10: 2 | Q10: 5 | R10: Headrest could have been more better | S10: Space for the feet should be a little more spacious
A11: TRUE | B11: A010 | C11: Siwa | D11: Siwa | E11: No discomfort | F11: NA | G11: No | H11: No | I11: Restricted space for movement | K11: 1 | L11: 5 | M11: 6 | N11: 4 | O11: 3 | P11: 7 | Q11: 2 | R11: Should make it .ore realistic tonallow people tonassess email or even take a nap | S11: Should make it.more realiatic dor people ro take.nap as not everyone will.be awake thru the 6 hours in real flight
A12: TRUE | B12: A011 | C12: Elizabeth Li | D12: Elizabeth Li | E12: Slight discomfort | F12: The inability to adjust the seat. | G12: Not really | H12: Initial load, has some issues but refresh was ok | I12: Restricted space for movement,Seat angle | K12: 1 | L12: 7 | M12: 2 | N12: 5 | O12: 6 | P12: 4 | Q12: 3 | R12: Na | S12: Na
